<?xml version="1.0" ?>
<robot name="iris_demo" 
      xmlns:xacro="http://ros.org/wiki/xacro">

  <origin rpy="0 0 0" xyz="0    0     0.19492"/>
  <joint name="iris/ground_truth/odometry_sensorgt_joint" type="revolute">
    <parent link="base_link"/>
    <child link="iris/ground_truth/odometry_sensorgt_link"/>
    <origin rpy="0 0 0" xyz="0      0      0"/>
    <axis xyz="0 0 1"/>
    <limit effort="0.0" lower="0.0" upper="0.0" velocity="0.0"/>
  </joint>
  <joint name="iris/imu_joint" type="revolute">
    <parent link="base_link"/>
    <child link="iris/imu_link"/>
    <origin rpy="0 0 0" xyz="0      0      0"/>
    <axis xyz="0 0 1"/>
    <limit effort="0.0" lower="0.0" upper="0.0" velocity="0.0"/>
  </joint>
  <joint name="rotor_0_joint" type="revolute">
    <parent link="base_link"/>
    <child link="rotor_0"/>
    <origin rpy="0 0 0" xyz="0.13    -0.22     0.023"/>
    <axis xyz="0 0 1"/>
    <limit effort="0.0" lower="-1e+16" upper="1e+16" velocity="0.0"/>
  </joint>
  <joint name="rotor_1_joint" type="revolute">
    <parent link="base_link"/>
    <child link="rotor_1"/>
    <origin rpy="0 0 0" xyz="-0.13     0.2      0.023"/>
    <axis xyz="0 0 1"/>
    <limit effort="0.0" lower="-1e+16" upper="1e+16" velocity="0.0"/>
  </joint>
  <joint name="rotor_2_joint" type="revolute">
    <parent link="base_link"/>
    <child link="rotor_2"/>
    <origin rpy="0 0 0" xyz="0.13    0.22    0.023"/>
    <axis xyz="0 0 1"/>
    <limit effort="0.0" lower="-1e+16" upper="1e+16" velocity="0.0"/>
  </joint>
  <joint name="rotor_3_joint" type="revolute">
    <parent link="base_link"/>
    <child link="rotor_3"/>
    <origin rpy="0 0 0" xyz="-0.13    -0.2      0.023"/>
    <axis xyz="0 0 1"/>
    <limit effort="0.0" lower="-1e+16" upper="1e+16" velocity="0.0"/>
  </joint>
  <link name="base_link">
    <inertial>
      <mass value="1.5"/>
      <origin rpy="0 0 0" xyz="0 0 0"/>
      <inertia ixx="0.008" ixy="0" ixz="0" iyy="0.015" iyz="0" izz="0.017"/>
    </inertial>
    <collision name="base_link">
      <origin rpy="0 0 0" xyz="0      0      -0.08"/>
      <geometry>
        <box size="0.47 0.47 0.23"/>
      </geometry>
    </collision>
    <visual name="base_link">
      <geometry>
        <mesh filename="file:///home/motaz/iris/src/iris_drone/models/iris_with_standoffs/meshes/iris.dae" scale="1.0 1.0 1.0"/>
      </geometry>
    </visual>
    <!--visual name="front_left_leg">
      <origin rpy="0 0 0" xyz="0.123   0.22    -0.11"/>
      <geometry>
        <cylinder length="0.17" radius="0.005"/>
      </geometry>
    </visual>
    <visual name="front_right_leg">
      <origin rpy="0 0 0" xyz="0.123   -0.22     -0.11"/>
      <geometry>
        <cylinder length="0.17" radius="0.005"/>
      </geometry>
    </visual>
    <visual name="rear_left_leg">
      <origin rpy="0 0 0" xyz="-0.14     0.21     -0.11"/>
      <geometry>
        <cylinder length="0.17" radius="0.005"/>
      </geometry>
    </visual>
    <visual name="rear_right_leg">
      <origin rpy="0 0 0" xyz="-0.14    -0.21     -0.11"/>
      <geometry>
        <cylinder length="0.17" radius="0.005"/>
      </geometry>
    </visual-->
  </link>

  <link name="base_footprint_xacro"/>

  <joint name="base_joint" type="fixed">
    <parent link="base_footprint_xacro"/>
    <child link="base_link"/>
    <origin xyz="0.0 0.0 0.0" rpy="0 0 0"/>
  </joint>
  <link name="iris/ground_truth/odometry_sensorgt_link">
    <inertial>
      <mass value="0.15"/>
      <origin rpy="0 0 0" xyz="0 0 0"/>
      <inertia ixx="0.0001" ixy="0" ixz="0" iyy="0.0002" iyz="0" izz="0.0002"/>
    </inertial>
  </link>
  <link name="iris/imu_link">
    <inertial>
      <mass value="0.15"/>
      <origin rpy="0 0 0" xyz="0 0 0"/>
      <inertia ixx="0.00001" ixy="0" ixz="0" iyy="0.00002" iyz="0" izz="0.00002"/>
    </inertial>
  </link>
  <link name="rotor_0">
    <inertial>
      <mass value="0.025"/>
      <origin rpy="0 0 0" xyz="0 0 0"/>
      <inertia ixx="9.75e-06" ixy="0" ixz="0" iyy="0.000166704" iyz="0" izz="0.000167604"/>
    </inertial>
    <collision name="rotor_0">
      <origin rpy="0 0 0" xyz="0 0 0"/>
      <geometry>
        <cylinder length="0.005" radius="0.1"/>
      </geometry>
    </collision>
    <visual name="rotor_0">
      <origin rpy="0 0 0" xyz="0 0 0"/>
      <geometry>
        <mesh filename="file:///home/motaz/iris/src/iris_drone/models/iris_with_standoffs/meshes/iris_prop_ccw.dae" scale="1 1 1"/>
      </geometry>
    </visual>
  </link>
  <link name="rotor_1">
    <inertial>
      <mass value="0.025"/>
      <origin rpy="0 0 0" xyz="0 0 0"/>
      <inertia ixx="9.75e-06" ixy="0" ixz="0" iyy="0.000166704" iyz="0" izz="0.000167604"/>
    </inertial>
    <collision name="rotor_1">
      <origin rpy="0 0 0" xyz="0 0 0"/>
      <geometry>
        <cylinder length="0.005" radius="0.1"/>
      </geometry>
    </collision>
    <visual name="rotor_1_visual">
      <origin rpy="0 0 0" xyz="0 0 0"/>
      <geometry>
        <mesh filename="file:///home/motaz/iris/src/iris_drone/models/iris_with_standoffs/meshes/iris_prop_ccw.dae" scale="1 1 1"/>
      </geometry>
    </visual>
  </link>
  <link name="rotor_2">
    <inertial>
      <mass value="0.025"/>
      <origin rpy="0 0 0" xyz="0 0 0"/>
      <inertia ixx="9.75e-06" ixy="0" ixz="0" iyy="0.000166704" iyz="0" izz="0.000167604"/>
    </inertial>
    <collision name="rotor_2">
      <origin rpy="0 0 0" xyz="0 0 0"/>
      <geometry>
        <cylinder length="0.005" radius="0.1"/>
      </geometry>
    </collision>
    <visual name="rotor_2">
      <origin rpy="0 0 0" xyz="0 0 0"/>
      <geometry>
        <mesh filename="file:///home/motaz/iris/src/iris_drone/models/iris_with_standoffs/meshes/iris_prop_cw.dae" scale="1 1 1"/>
      </geometry>
    </visual>
  </link>
  <link name="rotor_3">
    <inertial>
      <mass value="0.025"/>
      <origin rpy="0 0 0" xyz="0 0 0"/>
      <inertia ixx="9.75e-06" ixy="0" ixz="0" iyy="0.000166704" iyz="0" izz="0.000167604"/>
    </inertial>
    <collision name="rotor_3">
      <origin rpy="0 0 0" xyz="0 0 0"/>
      <geometry>
        <cylinder length="0.005" radius="0.1"/>
      </geometry>
    </collision>
    <visual name="rotor_3">
      <origin rpy="0 0 0" xyz="0 0 0"/>
      <geometry>
        <mesh filename="file:///home/motaz/iris/src/iris_drone/models/iris_with_standoffs/meshes/iris_prop_cw.dae" scale="1 1 1"/>
      </geometry>
    </visual>
  </link>

  <link name="base_scan">
    <inertial>
      <mass value="0.1"/>
      <inertia ixx="0.000166667" ixy="0.0" ixz="0.0" iyy="0.000166667" iyz="0.0" izz="0.000166667"/>
    </inertial>
    <visual>
      <geometry>
        <box size="0.05 0.05 0.05"/>
      </geometry>
      <material name="black">
        <color rgba="0 0 0 1"/>
      </material>
    </visual>
    <collision>
      <geometry>
        <box size="0.05 0.05 0.05"/>
      </geometry>
    </collision>
  </link>

  <!-- Joint definition -->
  <joint name="lidar_joint" type="revolute">
    <parent link="base_link"/>
    <child link="base_scan"/>
    <origin xyz="0 0 0" rpy="0 0 0"/>
    <axis xyz="0 0 1"/>
    <limit lower="0" upper="0" effort="0" velocity="0"/>
    <dynamics damping="1" friction="0"/>
  </joint>

<!-- 
  <link name="gimbal_base_link">
    <inertial>
      <mass value="0.2"/>
      <inertia ixx="0.0001" ixy="0" ixz="0" iyy="0.0001" iyz="0" izz="0.0001"/>
      <origin xyz="0 0 0" rpy="0 0 0"/>
    </inertial>
    <visual name="base_main_viz">
      <origin xyz="0 -0.01 -0.12" rpy="1.57 0 1.57"/>
      <geometry>
        <mesh filename="file:///home/motaz/iris/src/iris_drone/models/gimbal_small_2d_edit/meshes/base_main.dae" scale="0.001 0.001 0.001"/>
      </geometry>
      <material name="black">
        <color rgba="0 0 0 1"/>
      </material>
    </visual>
    <visual name="base_arm_viz">
      <origin xyz="0 -0.01 -0.12" rpy="1.57 0 1.57"/>
      <geometry>
        <mesh filename="file:///home/motaz/iris/src/iris_drone/models/gimbal_small_2d_edit/meshes/base_arm.dae" scale="0.001 0.001 0.001"/>
      </geometry>
      <material name="black">
        <color rgba="0 0 0 1"/>
      </material>
    </visual>
    <collision name="base_col">
      <origin xyz="0.01 0.0075 -0.025" rpy="0 0 0"/>
      <geometry>
        <box size="0.1 0.05 0.15"/>
      </geometry>
    </collision>
  </link>

  <joint name="iris_gimbal_mount" type="revolute">
    <parent link="base_link"/>
    <child link="gimbal_base_link"/>
    <origin xyz="0 -0.01 0.070" rpy="1.57 0 1.57"/>
    <axis xyz="0 0 1"/>
    <limit lower="0" upper="0" effort="0" velocity="0"/>
  </joint>

  <link name="tilt_link">
    <inertial>
      <mass value="0.01"/>
      <inertia ixx="0.00001" ixy="0" ixz="0" iyy="0.00001" iyz="0" izz="0.00001"/>
      <origin xyz="0 0 0" rpy="0 0 0"/>
    </inertial>
    <visual name="tilt_viz">
      <origin xyz="0 0 -0.105" rpy="1.57 1.57 0"/>
      <geometry>
        <mesh filename="file:///home/motaz/iris/src/iris_drone/models/gimbal_small_2d_edit/meshes/tilt.dae" scale="0.001 0.001 0.001"/>
      </geometry>
      <material name="grey">
        <color rgba="0.5 0.5 0.5 1"/>
      </material>
    </visual>
    <collision name="tilt_col">
      <origin xyz="0 -0.01 -0.105" rpy="1.57 1.57 0"/>
      <geometry>
        <mesh filename="file:///home/motaz/iris/src/iris_drone/models/gimbal_small_2d_edit/meshes/tilt.dae" scale="0.001 0.001 0.001"/>
      </geometry>
    </collision>
    <visual name="camera_viz">
      <origin xyz="0 -0.01 -0.10" rpy="-1.57 -1.57 0"/>
      <geometry>
        <cylinder radius="0.025" length="0.050"/>
      </geometry>
      <material name="grey">
        <color rgba="0.5 0.5 0.5 1"/>
      </material>
    </visual>
    <collision name="camera_col">
      <origin xyz="0 -0.01 -0.10" rpy="-1.57 -1.57 0"/>
      <geometry>
        <cylinder radius="0.025" length="0.050"/>
      </geometry>
    </collision>
  </link>

  <joint name="tilt_joint" type="revolute">
    <parent link="gimbal_base_link"/>
    <child link="tilt_link"/>
    <origin xyz="0 -0.01 -0.10" rpy="0 0 0"/>
    <axis xyz="1 0 0"/>
    <limit lower="-0.1" upper="3.14159265" effort="10" velocity="1"/>
    <dynamics damping="0.5"/>
  </joint> -->





<!-- <joint name="front_left_leg_joint" type="fixed">
    <parent link="base_link"/>
    <child link="front_left_leg"/>
    <origin rpy="0 0 0" xyz="0      0      0"/>
  </joint>

  <link name="front_left_leg">
    <inertial>
      <mass value="0.0001"/>
      <origin rpy="0 0 0" xyz="0.123   0.22    -0.11"/>
      <inertia ixx="0.00000001" ixy="0" ixz="0" iyy="0.00000001" iyz="0" izz="0.00000001"/>
    </inertial>
    <collision name="front_left_leg">
      <origin rpy="0 0 0" xyz="0.123   0.22    -0.11"/>
      <geometry>
        <cylinder length="0.19" radius="0.005"/>
      </geometry>
    </collision>
    <visual name="front_left_leg">
      <origin rpy="0 0 0" xyz="0.123   0.22    -0.11"/>
      <geometry>
        <cylinder length="0.19" radius="0.005"/>
      </geometry>
    </visual>
  </link>

  <joint name="front_right_leg_joint" type="fixed">
    <parent link="base_link"/>
    <child link="front_right_leg"/>
    <origin rpy="0 0 0" xyz="0      0      0"/>
  </joint>

  <link name="front_right_leg">
    <inertial>
      <mass value="0.0001"/>
      <origin rpy="0 0 0" xyz="0.123   -0.22     -0.11"/>
      <inertia ixx="0.00000001" ixy="0" ixz="0" iyy="0.00000001" iyz="0" izz="0.00000001"/>
    </inertial>
    <collision name="front_right_leg">
      <origin rpy="0 0 0" xyz="0.123   -0.22     -0.11"/>
      <geometry>
        <cylinder length="0.19" radius="0.005"/>
      </geometry>
    </collision>
    <visual name="front_right_leg">
      <origin rpy="0 0 0" xyz="0.123   -0.22     -0.11"/>
      <geometry>
        <cylinder length="0.19" radius="0.005"/>
      </geometry>
    </visual>
  </link>

  <joint name="rear_left_leg_joint" type="fixed">
    <parent link="base_link"/>
    <child link="rear_left_leg"/>
    <origin rpy="0 0 0" xyz="0      0      0"/>
  </joint>

  <link name="rear_left_leg">
    <inertial>
      <mass value="0.0001"/>
      <origin rpy="0 0 0" xyz="-0.14     0.21     -0.11"/>
      <inertia ixx="0.00000001" ixy="0" ixz="0" iyy="0.00000001" iyz="0" izz="0.00000001"/>
    </inertial>
    <collision name="rear_left_leg">
      <origin rpy="0 0 0" xyz="-0.14     0.21     -0.11"/>
      <geometry>
        <cylinder length="0.19" radius="0.005"/>
      </geometry>
    </collision>
    <visual name="rear_left_leg">
      <origin rpy="0 0 0" xyz="-0.14     0.21     -0.11"/>
      <geometry>
        <cylinder length="0.19" radius="0.005"/>
      </geometry>
    </visual>
  </link>

  <joint name="rear_right_leg_joint" type="fixed">
    <parent link="base_link"/>
    <child link="rear_right_leg"/>
    <origin rpy="0 0 0" xyz="0      0      0"/>
  </joint>

  <link name="rear_right_leg">
    <inertial>
      <mass value="0.0001"/>
      <origin rpy="0 0 0" xyz="-0.14    -0.21     -0.11"/>
      <inertia ixx="0.00000001" ixy="0" ixz="0" iyy="0.00000001" iyz="0" izz="0.00000001"/>
    </inertial>
    <collision name="rear_right_leg">
      <origin rpy="0 0 0" xyz="-0.14    -0.21     -0.11"/>
      <geometry>
        <cylinder length="0.19" radius="0.005"/>
      </geometry>
    </collision>
    <visual name="rear_right_leg">
      <origin rpy="0 0 0" xyz="-0.14    -0.21     -0.11"/>
      <geometry>
        <cylinder length="0.19" radius="0.005"/>
      </geometry>
    </visual>
  </link> -->


  <!-- <gazebo reference="iris/imu_joint">
    <disableFixedJointLumping>true</disableFixedJointLumping> 
    <preserveFixedJoint>true</preserveFixedJoint>
  </gazebo>
  <gazebo reference="iris/ground_truth/odometry_sensorgt_joint">
    <disableFixedJointLumping>true</disableFixedJointLumping> 
    <preserveFixedJoint>true</preserveFixedJoint>
  </gazebo>
  <gazebo reference="front_left_leg_joint">
    <disableFixedJointLumping>true</disableFixedJointLumping> 
    <preserveFixedJoint>true</preserveFixedJoint>
  </gazebo>
  <gazebo reference="front_right_leg_joint">
    <disableFixedJointLumping>true</disableFixedJointLumping> 
    <preserveFixedJoint>true</preserveFixedJoint>
  </gazebo>
  <gazebo reference="rear_left_leg_joint">
    <disableFixedJointLumping>true</disableFixedJointLumping> 
    <preserveFixedJoint>true</preserveFixedJoint>
  </gazebo>
  <gazebo reference="rear_right_leg_joint">
    <disableFixedJointLumping>true</disableFixedJointLumping> 
    <preserveFixedJoint>true</preserveFixedJoint>
  </gazebo> -->


  <!-- <gazebo reference="base_link">
    <material>Gazebo/FlatBlack</material>
  </gazebo>
  <gazebo reference="front_left_leg">
    <material>Gazebo/FlatBlack</material>
  </gazebo>
  <gazebo reference="rotor_0">
    <material>Gazebo/Blue</material>
  </gazebo>
  <gazebo reference="rotor_1">
    <material>Gazebo/DarkGrey</material>
  </gazebo>
  <gazebo reference="rotor_2">
    <material>Gazebo/Blue</material>
  </gazebo>
  <gazebo reference="rotor_3">
    <material>Gazebo/DarkGrey</material>
  </gazebo>
  <gazebo reference="front_left_leg">
    <material>Gazebo/Orange</material>
  </gazebo>
  <gazebo reference="front_right_leg">
    <material>Gazebo/Orange</material>
  </gazebo>
  <gazebo reference="rear_right_leg">
    <material>Gazebo/Orange</material>
  </gazebo>
  <gazebo reference="rear_left_leg">
    <material>Gazebo/Orange</material>
  </gazebo> -->

  <!--Gazebo Plugins-->
  <!-- <gazebo>
    <plugin name="rotor_0_blade_1" filename="libLiftDragPlugin.so">
      <a0>0.1</a0>
      <alpha_stall>1.4</alpha_stall>
      <cla>0.2500</cla>
      <cda>0.10</cda>
      <cma>0.00</cma>
      <cla_stall>-0.025</cla_stall>
      <cda_stall>0.0</cda_stall>
      <cma_stall>0.0</cma_stall>
      <area>0.2</area>
      <air_density>1.2041</air_density>
      <cp>0.084 0 0</cp>
      <forward>0 1 0</forward>
      <upward>0 0 1</upward>
      <link_name>iris::rotor_0</link_name>
    </plugin>
  </gazebo>

  <gazebo>
    <plugin name="rotor_0_blade_2" filename="libLiftDragPlugin.so">
      <a0>0.1</a0>
      <alpha_stall>1.4</alpha_stall>
      <cla>0.2500</cla>
      <cda>0.10</cda>
      <cma>0.00</cma>
      <cla_stall>-0.025</cla_stall>
      <cda_stall>0.0</cda_stall>
      <cma_stall>0.0</cma_stall>
      <area>0.2</area>
      <air_density>1.2041</air_density>
      <cp>-0.084 0 0</cp>
      <forward>0 -1 0</forward>
      <upward>0 0 1</upward>
      <link_name>iris::rotor_0</link_name>
    </plugin>
  </gazebo>

  <gazebo>
    <plugin name="rotor_1_blade_1" filename="libLiftDragPlugin.so">
      <a0>0.1</a0>
      <alpha_stall>1.4</alpha_stall>
      <cla>0.2500</cla>
      <cda>0.10</cda>
      <cma>0.00</cma>
      <cla_stall>-0.025</cla_stall>
      <cda_stall>0.0</cda_stall>
      <cma_stall>0.0</cma_stall>
      <area>0.2</area>
      <air_density>1.2041</air_density>
      <cp>0.084 0 0</cp>
      <forward>0 1 0</forward>
      <upward>0 0 1</upward>
      <link_name>iris::rotor_1</link_name>
    </plugin>
  </gazebo>

  <gazebo>
    <plugin name="rotor_1_blade_2" filename="libLiftDragPlugin.so">
      <a0>0.1</a0>
      <alpha_stall>1.4</alpha_stall>
      <cla>0.2500</cla>
      <cda>0.10</cda>
      <cma>0.00</cma>
      <cla_stall>-0.025</cla_stall>
      <cda_stall>0.0</cda_stall>
      <cma_stall>0.0</cma_stall>
      <area>0.2</area>
      <air_density>1.2041</air_density>
      <cp>-0.084 0 0</cp>
      <forward>0 -1 0</forward>
      <upward>0 0 1</upward>
      <link_name>iris::rotor_1</link_name>
    </plugin>
  </gazebo>

  <gazebo>
    <plugin name="rotor_2_blade_1" filename="libLiftDragPlugin.so">
      <a0>0.1</a0>
      <alpha_stall>1.4</alpha_stall>
      <cla>0.2500</cla>
      <cda>0.10</cda>
      <cma>0.00</cma>
      <cla_stall>-0.025</cla_stall>
      <cda_stall>0.0</cda_stall>
      <cma_stall>0.0</cma_stall>
      <area>0.2</area>
      <air_density>1.2041</air_density>
      <cp>0.084 0 0</cp>
      <forward>0 -1 0</forward>
      <upward>0 0 1</upward>
      <link_name>iris::rotor_2</link_name>
    </plugin>
  </gazebo>

  <gazebo>
    <plugin name="rotor_2_blade_2" filename="libLiftDragPlugin.so">
      <a0>0.1</a0>
      <alpha_stall>1.4</alpha_stall>
      <cla>0.2500</cla>
      <cda>0.10</cda>
      <cma>0.00</cma>
      <cla_stall>-0.025</cla_stall>
      <cda_stall>0.0</cda_stall>
      <cma_stall>0.0</cma_stall>
      <area>0.2</area>
      <air_density>1.2041</air_density>
      <cp>-0.084 0 0</cp>
      <forward>0 1 0</forward>
      <upward>0 0 1</upward>
      <link_name>iris::rotor_2</link_name>
    </plugin>
  </gazebo>

  <gazebo>
    <plugin name="rotor_3_blade_1" filename="libLiftDragPlugin.so">
      <a0>0.1</a0>
      <alpha_stall>1.4</alpha_stall>
      <cla>0.2500</cla>
      <cda>0.10</cda>
      <cma>0.00</cma>
      <cla_stall>-0.025</cla_stall>
      <cda_stall>0.0</cda_stall>
      <cma_stall>0.0</cma_stall>
      <area>0.2</area>
      <air_density>1.2041</air_density>
      <cp>0.084 0 0</cp>
      <forward>0 -1 0</forward>
      <upward>0 0 1</upward>
      <link_name>iris::rotor_3</link_name>
    </plugin>
  </gazebo>

  <gazebo>
    <plugin name="rotor_3_blade_2" filename="libLiftDragPlugin.so">
      <a0>0.1</a0>
      <alpha_stall>1.4</alpha_stall>
      <cla>0.2500</cla>
      <cda>0.10</cda>
      <cma>0.00</cma>
      <cla_stall>-0.025</cla_stall>
      <cda_stall>0.0</cda_stall>
      <cma_stall>0.0</cma_stall>
      <area>0.2</area>
      <air_density>1.2041</air_density>
      <cp>-0.084 0 0</cp>
      <forward>0 1 0</forward>
      <upward>0 0 1</upward>
      <link_name>iris::rotor_3</link_name>
    </plugin>
  </gazebo>

  <gazebo>
    <plugin name="arducopter_plugin" filename="libArduPilotPlugin.so">
      <fdm_addr>127.0.0.1</fdm_addr>
      <fdm_port_in>9002</fdm_port_in>
      <fdm_port_out>9003</fdm_port_out>
      <modelXYZToAirplaneXForwardZDown>0 0 0 3.141593 0 0</modelXYZToAirplaneXForwardZDown>
      <gazeboXYZToNED>0 0 0 3.141593 0 0</gazeboXYZToNED>
      <imuName>iris::iris/imu_link::imu_sensor</imuName>
      <connectionTimeoutMaxCount>5</connectionTimeoutMaxCount>
      <control channel="0">
        <type>VELOCITY</type>
        <offset>0</offset>
        <p_gain>0.20</p_gain>
        <i_gain>0</i_gain>
        <d_gain>0</d_gain>
        <i_max>0</i_max>
        <i_min>0</i_min>
        <cmd_max>2.5</cmd_max>
        <cmd_min>-2.5</cmd_min>
        <jointName>iris::rotor_0_joint</jointName>
        <multiplier>838</multiplier>
        <controlVelocitySlowdownSim>1</controlVelocitySlowdownSim>
      </control>
      <control channel="1">
        <type>VELOCITY</type>
        <offset>0</offset>
        <p_gain>0.20</p_gain>
        <i_gain>0</i_gain>
        <d_gain>0</d_gain>
        <i_max>0</i_max>
        <i_min>0</i_min>
        <cmd_max>2.5</cmd_max>
        <cmd_min>-2.5</cmd_min>
        <jointName>iris::rotor_1_joint</jointName>
        <multiplier>838</multiplier>
        <controlVelocitySlowdownSim>1</controlVelocitySlowdownSim>
      </control>
      <control channel="2">
        <type>VELOCITY</type>
        <offset>0</offset>
        <p_gain>0.20</p_gain>
        <i_gain>0</i_gain>
        <d_gain>0</d_gain>
        <i_max>0</i_max>
        <i_min>0</i_min>
        <cmd_max>2.5</cmd_max>
        <cmd_min>-2.5</cmd_min>
        <jointName>iris::rotor_2_joint</jointName>
        <multiplier>-838</multiplier>
        <controlVelocitySlowdownSim>1</controlVelocitySlowdownSim>
      </control>
      <control channel="3">
        <type>VELOCITY</type>
        <offset>0</offset>
        <p_gain>0.20</p_gain>
        <i_gain>0</i_gain>
        <d_gain>0</d_gain>
        <i_max>0</i_max>
        <i_min>0</i_min>
        <cmd_max>2.5</cmd_max>
        <cmd_min>-2.5</cmd_min>
        <jointName>iris::rotor_3_joint</jointName>
        <multiplier>-838</multiplier>
        <controlVelocitySlowdownSim>1</controlVelocitySlowdownSim>
      </control>
    </plugin>
  </gazebo>
 
  <gazebo reference="iris/imu_link">
    <gravity>true</gravity>
    <sensor name="imu_sensor" type="imu">
      <pose>0 0 0 3.141593 0 0</pose>
      <always_on>1</always_on>
      <update_rate>1000.0</update_rate>    
      <plugin filename="libgazebo_ros_imu_sensor.so" name="imu_plugin">
          <topicName>imu</topicName>
          <bodyName>iris/imu_link</bodyName>
          <updateRateHZ>10.0</updateRateHZ>
          <gaussianNoise>0.0</gaussianNoise>
          <xyzOffset>0 0 0</xyzOffset>
          <rpyOffset>0 0 0</rpyOffset>
          <frameName>iris/imu_link</frameName>
          <initialOrientationAsReference>false</initialOrientationAsReference>
      </plugin>
    </sensor>
</gazebo>  -->

</robot>